Workbook

Sheet Database
A1: Barcode Image | B1: Code / SKU | C1: Item Name | D1: Qty Per Scan | E1: Counted Qty | F1: Qtty/box | G1: Price/unit
B2: TEST123 | C2: Test Item | D2: 1 | E2: 11
B3: COTININE-TEST-DEVICE | C3: Cotinine Test Device (Ref: DCT-102) | D3: 1 | E3: 134 | G3: 1.22
B4: HCG-URINE-PREG-CASSETTE | C4: hCG Urine Pregnancy Test Cassette ( Ref: PF453 / MPH11025HCG) | D4: 1 | E4: 111 | G4: 0.96
B5: MULTI-DRUG-TEST-CUP | C5: Multi Panel Drug Urine Test Cup (Ref: HCDOAV-5) | D5: 1 | E5: 42 | G5: 3.2896
B6: PATIENT-GOWN-DISPOSABLE | C6: Patient Gown One-time (Ref: NON27046) | D6: 1 | E6: 60 | G6: 0.83
B7: PATIENT-GOWN-FABRIC | C7: Medline Patient gown fabric (Ref: MDTPG2RSBSTA) | D7: 1 | E7: 66 | G7: 2.31
B8: ANTI-EMBOLISM-STOCKINGS-XL | C8: Cardinal Health Anti-Embolism Stockings Knee Length XL (Ref: 7802) | D8: 1 | E8: 36 | G8: 4.3666
B9: ANTI-EMBOLISM-STOCKINGS-L | C9: Cardinal Health Anti-Embolism Stockings Knee Length Large (Ref: 7594) | D9: 1 | E9: 24 | G9: 4.3666
B10: ANTI-EMBOLISM-STOCKINGS-M | C10: Cardinal Health Anti-Embolism Stockings Knee Length Medium (Ref: 7115) | D10: 1 | E10: 24 | G10: 4.3666
B11: SLIPPERS-SKID-RESISTANT | C11: Medline Single Tread Slippers W/Skid-Resistant Soles (Ref: 44125Z) | D11: 1 | E11: 13 | G11: 0.7119
B12: PATIENT-BLANKET | C12: Medline Patient Blanket (Ref: NONDB4080) | D12: 1 | E12: 28 | G12: 4.737
B13: BOUFFANT-CAPS | C13: Medline Bouffant Caps (Ref: CRI1001) | D13: 1 | E13: 500 | F13: 100/box /5 boxes | G13: 0.01
B14: SURGEONS-CAPS | C14: Medline Surgeron's Caps (Ref: NON28625) | D14: 1 | E14: 200 | F14: 100/box | G14: 0.035
B15: SHOE-COVERS-LARGE | C15: Medline Shoe Covers Large (Ref: CRI2002) | D15: 1 | E15: 400 | F15: 100/box/ 4 boxes | G15: 0.0677
B16: NITRILE-GLOVES-S | C16: Exam Gloves Nitrile Size S (Ref: 5700631) | D16: 1 | E16: 0 | G16: 0.2135
B17: NITRILE-GLOVES-M | C17: Exam Gloves Nitrile Size M (Ref: 5700632) | D17: 1 | E17: 0 | G17: 0.2562
B18: NITRILE-GLOVES-L | C18: Exam Gloves Nitrile Size L (Ref: 5700633) | D18: 1 | E18: 1 | F18: 200/box | G18: 0.0766
B19: DRY-SKIN-SCRUB-TRAY | C19: Medline Premium Dry Skin Scrub Tray (Ref: DYND70661) | D19: 1 | E19: 29 | G19: 2.5115
B20: CHLORAPREP-26ML | C20: BD ChloraPrep 26ml Applicator (Ref: 930815) | D20: 1 | E20: 20 | G20: 9.1768
B21: OCUSOFT-LID-SCRUB | C21: Ocusoft Lid Scrub (Ref: 54799-301-90) | D21: 1 | E21: 0 | G21: 0.0255
B22: RETURN-ELECTRODE-ADULT-CABLE | C22: Bovie Disposable Split Adult Return Electrode with Cable (Ref: ESREC-1) | D22: 1 | E22: 7 | G22: 2.28
B23: FOLEY-CATH-TRAY-16FR | C23: Medline Silicone-Elastomer Coated Latex Foley Catheter Tray 16Fr (Ref:DYND11003) | D23: 1 | E23: 9 | G23: 8.83
B24: POST-SURGERY-BRA | C24: Post Surgery Bra | D24: 1 | E24: 0 | G24: 18.99
B25: ABDOMINAL-BINDER-62-74 | C25: McKesson Abdominal Binder 62-74 four panel (Ref: 155-79-89220) | D25: 1 | E25: 8 | G25: 13.48
B26: ABDOMINAL-BINDER-45-62 | C26: McKesson Abdominal Binder 45-62 four panel (Ref: 155-79-89091) | D26: 1 | E26: 7 | G26: 13.48
B27: ABDOMINAL-BINDER-30-45 | C27: McKesson Abdominal Binder 30-45 four panel (Ref: 155-79-89090) | D27: 1 | E27: 3 | G27: 13.48
B28: ABDOMINAL-BINDER-30-45-3PANEL | C28: McKesson Abdominal Binder 30-45 three panel (Ref: 155-79-89070) | D28: 1 | E28: 8 | G28: 13.48
B29: TABLE-COVER-50X90 | C29: Medline Table Cover 50" x 90" (Ref: DYNJP2316) | D29: 1 | E29: 53 | G29: 2.0367
B30: MAYO-STAND-COVER-REINFORCED | C30: Medline Mayo Stand Cover, Reinforced (Ref: DYNJP2500) | D30: 1 | E30: 50 | G30: 1.0647
... B59: INFILTRATION-TUBING-LARGEBORE | C59: Cellmyx Infiltration Large Bore Tubing (Ref: FAT-10002-IN) | D59: 1 | E59: 17 | G59: 22.7
B60: SYRINGE-30ML | C60: BD Syringe 30ml (Ref: 302832) | D60: 4 | E60: 214 | G60: $0.3341
B61: SYRINGE-20ML | C61: BD Syringe 20ml (Ref: 302830) | D61: 1 | E61: 120 | G61: $0.2587
B62: SYRINGE-10ML | C62: BD Syringe 10ml (Ref: 302995) | D62: 1 | E62: 647 | G62: $0.1207
B63: SYRINGE-5ML | C63: BD Syringe 5ml (Ref: 309646) | D63: 1 | E63: 201 | G63: $0.1173
B64: SYRINGE-3ML | C64: BD Syringe 3ml (Ref: 309657) | D64: 1 | E64: 136 | G64: $0.0747
B65: SYRINGE-1ML | C65: BD Syringe 1ml (Ref: 3096280) | D65: 1 | E65: 104 | G65: $0.3680
B66: SYRINGE-60ML | C66: Terumo Syringe 60ml (Ref: SS-60L) | D66: 1 | E66: 70 | G66: 0.56
B67: TOOMEY-SYRINGE-60ML | C67: Toomey Syringe 60ml monoject (Ref: 512956X / 560265) | D67: 1 | E67: 23 | G67: 1.99
B68: SALINE-SYRINGE-10ML | C68: PosiFlush Prefilled Normal Saline Syringe, 10 mL (Ref: B-D306547Z) | D68: 1 | E68: 120 | G68: 0.25
...

Sheet Sheet6
B1: TRIAMCINOLONE-40MG-ML | C1: Amneal Triamcinolone 40mg/ml | D1: 1 | E1: 9 | I1: =G1*E1 -> 0
B2: ARTIFICIAL-TEARS-15ML | C2: Gericare Artificial Tears (15ml) | D2: 1 | E2: 2 | I2: =G2*E2 -> 0
B3: IRON-SUCROSE-200MG-10ML-SANDOZ | C3: Sandoz Iron Sucrose Injection 10ml, 200mg (NDC: 0781-3487-70) | D3: 1 | E3: 1 | I3: =G3*E3 -> 0
B4: IRON-SUCROSE-200MG-10ML-MYLAN | C4: Mylan Iron Sucrose Injection 10ml, 200mg (NDC: 67457-639-00) | D4: 1 | E4: 4 | I4: =G4*E4 -> 0
B5: NEOMYCIN-POLYMYXIN-3.5G | C5: Neomycin and Polymyxin B Sulfates 3.5g (NDC: 24208-785-55) | D5: 1 | E5: 6 | I5: =G5*E5 -> 0
C6: Polymyxin B 500000 (NDC: 63323-321-10) | D6: 1 | E6: 10 | I6: =G6*E6 -> 0
B7: CHLORHEXIDINE-0.12PCT | C7: Rising Chlorhexidine gluconate 0.12% (NDC: 16571-128-48) | D7: 1 | E7: 1 | I7: =G7*E7 -> 0
B8: TETRACAINE-0.5PCT-5ML | C8: Tetracaine Hydrochloride 0.5% 5mL (NDC: 70069-596-01) | D8: 1 | E8: 1 | I8: =G8*E8 -> 0
B9: CEFTRIAXONE-250MG | C9: Ceftriaxone for injections, 250 mg (NDCL: 0409-7337-01) | D9: 1 | E9: 17 | I9: =G9*E9 -> 0
B10: AFRIN-NASAL-MIST-15ML | C10: Afrin Nasal Pump Mist 15ml (no drip, severe congestion) | D10: 1 | E10: 4 | I10: =G10*E10 -> 0
B11: ONDANSETRON-4MG-2ML | C11: Odansetron Injection 4mg/2ml (NDC: 60505-6130-5) | D11: 1 | E11: 69 | I11: =G11*E11 -> 0
B12: METOCLOPRAMIDE-10MG-2ML | C12: Metoclopramine 10mg/2ml (NDC: 23155-240-41) | D12: 1 | E12: 50 | I12: =G12*E12 -> 0
C13: DOPamine HCL (NDC:0409-5820-11) | D13: 1 | E13: 1 | I13: =G13*E13 -> 0
C14: Midazolam injection 10mg/10ml (NDC: 0641-6056-10) | D14: 1 | E14: 10 | I14: =G14*E14 -> 0
C15: Midazolam injection 5mg/5ml (NDC: 0409-2305-05) | D15: 1 | E15: 20 | I15: =G15*E15 -> 0
C16: Promethazine Hydrochloride 25mg/ml (NDC: 39822-5525-3) | D16: 1 | E16: 25 | I16: =G16*E16 -> 0
C17: Scopolamine Transdermal System 1mg/3days | D17: 1 | E17: 20 | I17: =G17*E17 -> 0
B18: MAG-SULFATE-50PCT-10ML | C18: Magnesium Sulfate Inection, 50%, 10 ML (NDC: 63323-06404) | D18: 1 | E18: 10 | I18: =G18*E18 -> 0
C19: HYDROmorphone HCL 1mg/ml (NDC: 0409-1283-31) | D19: 1 | E19: 17 | I19: =G19*E19 -> 0
C20: HYDROmorphone HCL 2mg/ml (NDC: 0633323-853-25) | D20: 1 | E20: 78 | I20: =G20*E20 -> 0
C21: Rygby Polyvinyl alcohol 1.4% lubricating eye drops 15mL (NDC: 0536-1408-94) | D21: 1 | E21: 2 | I21: =G21*E21 -> 0
C22: Phenylephrine HCL 10mg/Ml (NDC: 71288-807-02) | D22: 1 | E22: 43 | I22: =G22*E22 -> 0
C23: Flumazenil 5mg/5ml (NDC:0143-9784-01) | D23: 1 | E23: 2 | I23: =G23*E23 -> 0
C24: Esmolol Hydrochloride 100mg/10ml (NDC: 67457-182-00) | D24: 1 | E24: 6 | I24: =G24*E24 -> 0
B25: GLYCOPYRROLATE-0.2MG-ML | C25: Sagent Glycopyrrolate Injection 0.2mg/ml (NDC: 25021-796-01) | D25: 1 | E25: 100 | I25: =G25*E25 -> 0
C26: 10% Calcium Chloride Ingection 1g/10ml (NDC: 76329-3304-1) | D26: 1 | E26: 2 | I26: =G26*E26 -> 0
C27: Epinephrine 1mg/10ML (NDC: 76329-3318-1) | D27: 1 | E27: 2 | I27: =G27*E27 -> 0
C28: Atropine Sulfate 1mg/10ml (NDC: 76329-3340-1) | D28: 1 | E28: 1 | I28: =G28*E28 -> 0
C29: 50% Dextrose 50mL (NDC: 0409-6648-16) | D29: 1 | E29: 5 | I29: =G29*E29 -> 0
C30: Heparine 5000 1ml (NDC: 25021-402-01) | D30: 1 | E30: 7 | I30: =G30*E30 -> 0
C31: Epinephrine 1mg/ml (NDC: 54288-103-10) | D31: 1 | E31: 1 | I31: =G31*E31 -> 0
C32: Lidocaine HCl 2% 20mg/ml (NDC: 0409-0147-10) | D32: 1 | E32: 5 | I32: =G32*E32 -> 0
C33: Naloxone Hydrochloride 0.4mg/mL (NDC: 72603-590-10) | D33: 1 | E33: 6 | I33: =G33*E33 -> 0
B34: LIDOCAINE-0.5-50ML | C34: Lidocaine 0.5% 5mg/ml 50ml (NDC: 0409-3177-01/06) | D34: 1 | E34: 32 | I34: =G34*E34 -> 0
C35: Porpofor Injectable 500mg/50ml (NDC: 16714-977-20) | D35: 1 | E35: 26 | I35: =G35*E35 -> 0

Sheet Scan
A1: Scan Here | B1: Status

Sheet Count Log
A1: SKINUVA-BAG | B1: Code / SKU | C1: Item Name | D1: Qty Added | E1: Status
A2: 46163.501 | B2: TEST123 | C2: Test Item | D2: 1 | E2: Added
A3: 46163.501 | B3: TEST123 | C3: Test Item | D3: 1 | E3: Added
A4: 46163.509 | B4: TEST123 | C4: Test Item | D4: 1 | E4: Added
A5: 46163.509 | B5: TEST123 | C5: Test Item | D5: 1 | E5: Added
A6: 46163.511 | B6: TEST123 | C6: Test Item | D6: 1 | E6: Added
A7: 46163.512 | B7: TEST123 | C7: Test Item | D7: 1 | E7: Added
A8: 46163.52 | B8: TEST123 | C8: Test Item | D8: 1 | E8: Added
A9: 46163.526 | B9: COTININE-TEST-DEVICE | C9: Cotinine Test Device | D9: 1 | E9: Added
A10: 46163.528 | B10: HCG-URINE-PREG-CASSETTE | C10: hCG Urine Pregnancy Test Cassette | D10: 1 | E10: Added
A11: 46163.536 | B11: TEST123 | C11: Test Item | D11: 1 | E11: Added
A12: 46163.536 | B12: TEST123 | C12: Test Item | D12: 1 | E12: Added
A13: 46163.536 | B13: TEST123 | C13: Test Item | D13: 1 | E13: Added
... A25: 46163.543 | B25: SKINUVA-BAG | C25: Plus Cosmetic and Skinuva bag | D25: 5 | E25: Added
A26: 46163.557 | B26: L-SPONGE-DOUBLE | C26: NOT FOUND | E26: Barcode/code not found in Database
A27: 46163.557 | B27: TONSIL-SPONGE-DOUBLE | C27: Medline Tonsil Sponge Double Strung (ref:MDS78912) | D27: 10 | E27: Added
A28: 46163.557 | B28: TONSIL-SPONGE-DOUBLE | C28: Medline Tonsil Sponge Double Strung (ref:MDS78912) | D28: 10 | E28: Added
A29: 46163.561 | B29: IV-ADMIN-SET | C29: Henry Schein IV Administration Set (ref:570-0887) | D29: 10 | E29: Added
A30: 46163.562 | B30: IV-ADMIN-SET | C30: Henry Schein IV Administration Set (ref:570-0887) | D30: 10 | E30: Added
A31: 46163.562 | B31: IV-ADMIN-SET | C31: Henry Schein IV Administration Set (ref:570-0887) | D31: 10 | E31: Added
A32: 46163.562 | B32: IV-ADMIN-SET | C32: Henry Schein IV Administration Set (ref:570-0887) | D32: 10 | E32: Added
A33: 46163.563 | B33: IV-ADMIN-SET | C33: Henry Schein IV Administration Set (ref:570-0887) | D33: 10 | E33: Added
A34: 46163.563 | B34: IV-ADMIN-SET | C34: Henry Schein IV Administration Set (ref:570-0887) | D34: 10 | E34: Added
A35: 46163.564 | B35: IV-ADMIN-SET | C35: Henry Schein IV Administration Set (ref:570-0887) | D35: 10 | E35: Added
A36: 46163.566 | B36: DISPOSABLE-NEBULIZER | C36: Medline Disposable Nebulizer (Ref:HCS4485) | D36: 10 | E36: Added
A37: 46163.566 | B37: DISPOSABLE-NEBULIZER | C37: Medline Disposable Nebulizer (Ref:HCS4485) | D37: 10 | E37: Added
A38: 46163.567 | B38: DISPOSABLE-NEBULIZER | C38: Medline Disposable Nebulizer (Ref:HCS4485) | D38: 10 | E38: Added
... A79: 46163.703 | B79: SYRINGE-30ML | C79: BD Syringe 30ml (Ref:302832) | D79: 4 | E79: Added

Sheet Лист5
A1: Bag count | B1: Amount | D1: Multiply by 13 instead of 5
A2: Medline Surgical Skin Marker (Ref: DYNJSM01) | B2: 1 | C2: =B2*5 -> 5 | D2: =B2*13 -> 13
A3: Medline O.R towels (Ref: MDT2168284) | B3: 3 | C3: =B3*5 -> 15 | D3: =B3*13 -> 39
A4: Medline Contro-Bulb Syringe 60ml (Ref:DYND20125) | B4: 1 | C4: =B4*5 -> 5 | D4: =B4*13 -> 13
A5: Medline Yankauer with bulb tip no control vent (Ref: DYND50130) | B5: 1 | C5: =B5*5 -> 5 | D5: =B5*13 -> 13
A6: Medline Flexible Light handle cover (Ref: DYNJLHS1) | B6: 1 | C6: =B6*5 -> 5 | D6: =B6*13 -> 13
A7: CardinalHealth Fabric Reinforced Surgical Gown XL (Ref: 9541) | B7: 2 | C7: =B7*5 -> 10 | D7: =B7*13 -> 26
A8: Medline Lap Sponges 18x18 (Ref:MDS241528) | B8: 2 | C8: =B8*5 -> 10 | D8: =B8*13 -> 26
A9: Medline Needle Counter 20ct (Ref: NC20FBR) | B9: 1 | C9: =B9*5 -> 5 | D9: =B9*13 -> 13
A10: Medline Tabel Cover (Ref:DYNJP2316) | B10: 1 | C10: =B10*5 -> 5 | D10: =B10*13 -> 13
A11: Medline Mayo Stand Cover Reinforced (Ref:DYNJP2500) | B11: 1 | C11: =B11*5 -> 5 | D11: =B11*13 -> 13
A12: Medline Cautery Pencil Rocker Stainless Steel Blade (Ref: ESRK3000) | B12: 1 | C12: =B12*5 -> 5 | D12: =B12*13 -> 13
A13: Medline Chest/Breast drape lvl 4 (Ref:DYNJP2491) | B13: 1 | C13: =B13*5 -> 5 | D13: =B13*13 -> 13
... A19: Megadyne Short Protected Bovie Tip (Ref:0012M) | B19: 1 | C19: =B19*5 -> 5 | D19: =B19*13 -> 13

Sheet By Category
A1: Category | B1: Subcategory | C1: Item Name | D1: Reference / NDC / MFR | E1: Source Line | F1: Notes
A2: Implants / Implant Accessories / Scaffolds | B2: Scaffold / mesh | C2: Galatea GalaFLEX 3DR Scaffold Large (Ref: FR3D05) | D2: FR3D05 | E2: 396
A3: Implants / Implant Accessories / Scaffolds | B3: Implant accessory | C3: Keller Funnel (Ref: HA005) | D3: HA005 | E3: 56
A4: Implants / Implant Accessories / Scaffolds | B4: Breast implants | C4: Mentor Siltex Round Moderate Plus 325cc (Ref: 354-3251) | D4: 354-3251 | E4: 471
A5: Implants / Implant Accessories / Scaffolds | B5: Breast implants | C5: Mentor Siltex Round Moderate Plus 400cc (Ref: 354-4400) | D5: 354-4400 | E5: 472
A6: Implants / Implant Accessories / Scaffolds | B6: Breast implants | C6: Mentor Smooth Round H-P 375 cc (Ref: 350-3754BC) | D6: 350-3754BC | E6: 483
A7: Implants / Implant Accessories / Scaffolds | B7: Breast implants | C7: Mentor Smooth Round H-P Saline 190cc-225cc (Ref:350-3190) | D7: 350-3190 | E7: 465
A8: Implants / Implant Accessories / Scaffolds | B8: Breast implants | C8: Mentor Smooth Round High-profile 275cc (Ref: 350-2754BC) | D8: 350-2754BC | E8: 454
A9: Implants / Implant Accessories / Scaffolds | B9: Breast implants | C9: Mentor Smooth Round High-profile 300cc (Ref: 350-3004BC) | D9: 350-3004BC | E9: 451
A10: Implants / Implant Accessories / Scaffolds | B10: Breast implants | C10: Mentor Smooth Round High-profile 325cc (Ref: 350-3254BC) | D10: 350-3254BC | E10: 452
A11: Implants / Implant Accessories / Scaffolds | B11: Breast implants | C11: Mentor Smooth Round High-profile 350cc (Ref: 350-3504BC) | D11: 350-3504BC | E11: 450
A12: Implants / Implant Accessories / Scaffolds | B12: Breast implants | C12: Mentor Smooth Round High-profile 400cc (Ref: 350-4004BC) | D12: 350-4004BC | E12: 453
A13: Implants / Implant Accessories / Scaffolds | B13: Breast implants | C13: Mentor Smooth Round High-profile 425cc (Ref: 350-4254BC) | D13: 350-4254BC | E13: 455
... A139: Medications / Pharmaceuticals | B139: Medication / pharmaceutical | C139: Acetaminophen Injection 10mg/ml (Ref: DA4100) (NDC: 0264-4100-90) | D139: DA4100; 0264-4100-90 | E139: 269
A140: Medications / Pharmaceuticals | B140: Medication / pharmaceutical | C140: Afrin Nasal Pump Mist 15ml (no drip, severe congestion) | E140: 504
A141: Medications / Pharmaceuticals | B141: Medication / pharmaceutical | C141: Albuterol Sulfate Inhalation Solution 2.5mg/3ml (NDC: 76204-200-01) | D141: 76204-200-01 | E141: 256
A142: Medications / Pharmaceuticals | B142: Medication / pharmaceutical | C142: Amneal Triamcinolone 40mg/ml | E142: 495
A143: Medications / Pharmaceuticals | B143: Medication / pharmaceutical | C143: Atropine Sulfate 1mg/10ml (NDC: 76329-3340-1) | D143: 76329-3340-1 | E143: 241
A144: Medications / Pharmaceuticals | B144: Medication / pharmaceutical | C144: Bupivacaine 5mg/ml (NDC: 0143-9331-10) | D144: 0143-9331-10 | E144: 263
A145: Medications / Pharmaceuticals | B145: Medication / pharmaceutical | C145: Camber Lidocaine 2% 20mg/ml 20ml (NDC: 31722-217-31) | D145: 31722-217-31 | E145: 222
A146: Medications / Pharmaceuticals | B146: Medication / pharmaceutical | C146: Camber Magnesium Sulfate 50% 500mg/ml (NDC: 31722-394-33) | D146: 31722-394-33 | E146: 266
A147: Medications / Pharmaceuticals | B147: Medication / pharmaceutical | C147: Cefazolin 1g/vial price per item for 1 vl (NDC: 60505-6142-5) | D147: 60505-6142-5 | E147: 237
A148: Medications / Pharmaceuticals | B148: Medication / pharmaceutical | C148: Ceftriaxone for injections, 250 mg (NDCL: 0409-7337-01) | D148: L | E148: 503
A149: Medications / Pharmaceuticals | B149: Medication / pharmaceutical | C149: Clindamycin 150MG/ML (Ref: 25021011502) | D149: 25021011502 | E149: 255
A150: Medications / Pharmaceuticals | B150: Medication / pharmaceutical | C150: Dexamethasone Sodium Phosphate 10mg/ml (NDC: 633323-506-01) | D150: 633323-506-01 | E150: 235
A151: Medications / Pharmaceuticals | B151: Medication / pharmaceutical | C151: Diphenhydramine 50MG/ML (NDC: 0641-0376-25) | D151: 0641-0376-25 | E151: 254
A152: Medications / Pharmaceuticals | B152: Medication / pharmaceutical | C152: DOPamine HCL (NDC:0409-5820-11) | D152: 0409-5820-11 | E152: 277
A153: Medications / Pharmaceuticals | B153: Medication / pharmaceutical | C153: Ephedrine Sulfate 50mg/ml (NDC: 0781-3269-95) | D153: 0781-3269-95 | E153: 249
A154: Medications / Pharmaceuticals | B154: Medication / pharmaceutical | C154: Epinephrine 1mg/10ML (NDC: 76329-3318-1) | D154: 76329-3318-1 | E154: 240
... A164: Medications / Pharmaceuticals | B164: Medication / pharmaceutical | C164: Gentamicin Injection 40mg/ml (NDC: 633323-010-02) | D164: 633323-010-02 | E164: 271
A165: Medications / Pharmaceuticals | B165: Medication / pharmaceutical | C165: Gericare Artificial Tears (15ml) | E165: 496
A166: Medications / Pharmaceuticals | B166: Medication / pharmaceutical | C166: Heparin 5000 1ml (NDC: 25021-402-01) | D166: 25021-402-01 | E166: 234
A167: Medications / Pharmaceuticals | B167: Medication / pharmaceutical | C167: Hydralazine 20mg/1ml (NDC: 633323-613-01) | D167: 633323-613-01 | E167: 251
A168: Medications / Pharmaceuticals | B168: Medication / pharmaceutical | C168: HYDROmorphone HCL 1mg/ml (NDC: 0409-1283-31) | D168: 0409-1283-31 | E168: 259
A169: Medications / Pharmaceuticals | B169: Medication / pharmaceutical | C169: HYDROmorphone HCL 2mg/ml (NDC: 0633323-853-25) | D169: 0633323-853-25 | E169: 260
A170: Medications / Pharmaceuticals | B170: Medication / pharmaceutical | C170: Ketamine Hydrochloride 50mg/ml (NDC: 25021-683-10) | D170: 25021-683-10 | E170: 228
A171: Medications / Pharmaceuticals | B171: Medication / pharmaceutical | C171: Ketorolac Tromethamine 30mg/ml (Ref: 72266011825) | D171: 72266011825 | E171: 257
A172: Medications / Pharmaceuticals | B172: Medication / pharmaceutical | C172: Labetalol Hydrochloride 5mg/ml (NDC: 72266-103-01) | D172: 72266-103-01 | E172: 248
A173: Medications / Pharmaceuticals | B173: Medication / pharmaceutical | C173: Lidocaine 0.5% 5mg/ml 50ml (NDC: 0409-3177-01/06) | D173: 0409-3177-01/06 | E173: 220
A174: Medications / Pharmaceuticals | B174: Medication / pharmaceutical | C174: Lidocaine 1% 10mg/ml 50ml (NDC: 0143-9577-01) | D174: 0143-9577-01 | E174: 221
...

Sheet Original Order
A1: Source Line | B1: Item Name | C1: Category | D1: Subcategory | E1: Reference / NDC / MFR
A2: 2 | B2: Test Item | C2: Uncategorized / Review | D2: Dummy item / confirm
A3: 3 | B3: Cotinine Test Device (Ref: DCT-102) | C3: Diagnostics / Testing / Monitoring | D3: Diagnostic / test / monitoring | E3: DCT-102
A4: 4 | B4: hCG Urine Pregnancy Test Cassette ( Ref: PF453 / MPH11025HCG) | C4: Diagnostics / Testing / Monitoring | D4: Diagnostic / test / monitoring | E4: PF453 / MPH11025HCG
A5: 5 | B5: Multi Panel Drug Urine Test Cup (Ref: HCDOAV-5) | C5: Diagnostics / Testing / Monitoring | D5: Diagnostic / test / monitoring | E5: HCDOAV-5
A6: 6 | B6: Patient Gown One-time (Ref: NON27046) | C6: Patient Care / Hygiene / Comfort | D6: Patient care / comfort | E6: NON27046
A7: 7 | B7: Medline Patient gown fabric (Ref: MDTPG2RSBSTA) | C7: Patient Care / Hygiene / Comfort | D7: Patient care / comfort | E7: MDTPG2RSBSTA
A8: 8 | B8: Cardinal Health Anti-Embolism Stockings Knee Length XL (Ref: 7802) | C8: Patient Garments / Compression / Supports | D8: Compression / support garment | E8: 7802
A9: 9 | B9: Cardinal Health Anti-Embolism Stockings Knee Length Large (Ref: 7594) | C9: Patient Garments / Compression / Supports | D9: Compression / support garment | E9: 7594
A10: 10 | B10: Cardinal Health Anti-Embolism Stockings Knee Length Medium (Ref: 7115) | C10: Patient Garments / Compression / Supports | D10: Compression / support garment | E10: 7115
A11: 11 | B11: Medline Single Tread Slippers W/Skid-Resistant Soles (Ref: 44125Z) | C11: Patient Care / Hygiene / Comfort | D11: Patient care / comfort | E11: 44125Z
A12: 12 | B12: Medline Patient Blanket (Ref: NONDB4080) | C12: Patient Care / Hygiene / Comfort | D12: Patient care / comfort | E12: NONDB4080
A13: 13 | B13: Medline Bouffant Caps (Ref: CRI1001) | C13: PPE / Gloves / Masks / Staff Apparel | D13: PPE / staff apparel | E13: CRI1001
A14: 14 | B14: Medline Surgeron's Caps (Ref: NON28625) | C14: PPE / Gloves / Masks / Staff Apparel | D14: PPE / staff apparel | E14: NON28625
... A23: 23 | B23: Medline Silicone-Elastomer Coated Latex Foley Catheter Tray 16Fr (Ref:DYND11003) | C23: Kits / Packs / Procedure Trays | D23: Kit / procedure tray | E23: DYND11003
A24: 24 | B24: Post Surgery Bra | C24: Patient Garments / Compression / Supports | D24: Compression / support garment
A25: 25 | B25: McKesson Abdominal Binder 62-74 four panel (Ref: 155-79-89220) | C25: Patient Garments / Compression / Supports | D25: Compression / support garment | E25: 155-79-89220
A26: 26 | B26: McKesson Abdominal Binder 45-62 four panel (Ref: 155-79-89091) | C26: Patient Garments / Compression / Supports | D26: Compression / support garment | E26: 155-79-89091
A27: 27 | B27: McKesson Abdominal Binder 30-45 four panel (Ref: 155-79-89090) | C27: Patient Garments / Compression / Supports | D27: Compression / support garment | E27: 155-79-89090
A28: 28 | B28: McKesson Abdominal Binder 30-45 three panel (Ref: 155-79-89070) | C28: Patient Garments / Compression / Supports | D28: Compression / support garment | E28: 155-79-89070
A29: 29 | B29: Medline Table Cover 50" x 90" (Ref: DYNJP2316) | C29: Drapes / Covers / OR Linens | D29: Drape / cover / linen | E29: DYNJP2316
A30: 30 | B30: Medline Mayo Stand Cover, Reinforced (Ref: DYNJP2500) | C30: Drapes / Covers / OR Linens | D30: Drape / cover / linen | E30: DYNJP2500
A31: 31 | B31: Cardinal Health Medium Sheet (Ref: 9355) | C31: Drapes / Covers / OR Linens | D31: Drape / cover / linen | E31: 9355
A32: 32 | B32: Cardinal Health Large Sheet (ref: 9446) | C32: Drapes / Covers / OR Linens | D32: Drape / cover / linen | E32: 9446
A33: 33 | B33: Cardinal Health Transverse Laparotomy Drape (Ref: 29421) | C33: Drapes / Covers / OR Linens | D33: Drape / cover / linen | E33: 29421
A34: 34 | B34: Medline O.R. Towels (Ref: MDT2168284) | C34: Gauze / Sponges / Towels / Applicators | D34: Gauze / sponge / applicator | E34: MDT2168284
A35: 35 | B35: Medline Chest/Breast Drape Lvl 4 (Ref: DYNJP2491) | C35: Drapes / Covers / OR Linens | D35: Drape / cover / linen | E35: DYNJP2491
A36: 36 | B36: Medline Non-Conductive Connecting Tubing 3mt log (Ref: DYND50221) | C36: Drains / Suction / Tubing / Canisters | D36: Drain / suction / tubing | E36: DYND50221
... A271: 271 | B271: Gentamicin Injection 40mg/ml (NDC: 633323-010-02) | C271: Medications / Pharmaceuticals | D271: Medication / pharmaceutical | E271: 633323-010-02
A272: 272 | B272: Scopolamine Transdermal System 1mg/3days | C272: Medications / Pharmaceuticals | D272: Medication / pharmaceutical
A273: 273 | B273: Promethazine Hydrochloride 25mg/ml (NDC: 39822-5525-3) | C273: Medications / Pharmaceuticals | D273: Medication / pharmaceutical | E273: 39822-5525-3
A274: 274 | B274: Midazolam injection 2mg/2ml (NDC: 21355-600-41) | C274: Medications / Pharmaceuticals | D274: Medication / pharmaceutical | E274: 21355-600-41
A275: 275 | B275: Midazolam injection 5mg/5ml (NDC: 0409-2305-05) | C275: Medications / Pharmaceuticals | D275: Medication / pharmaceutical | E275: 0409-2305-05
A276: 276 | B276: Midazolam injection 10mg/10ml (NDC: 0641-6056-10) | C276: Medications / Pharmaceuticals | D276: Medication / pharmaceutical | E276: 0641-6056-10
A277: 277 | B277: DOPamine HCL (NDC:0409-5820-11) | C277: Medications / Pharmaceuticals | D277: Medication / pharmaceutical | E277: 0409-5820-11
A278: 278 | B278: Medline Instant Cold Pack (Ref: MDS137020) | C278: Patient Care / Hygiene / Comfort | D278: Patient care / comfort | E278: MDS137020
A279: 279 | B279: Medline/Hudson Medium Concentration Oxygen Mask (Ref: HUDRHO41U) | C279: Anesthesia / Airway / Respiratory | D279: Airway / respiratory | E279: HUDRHO41U
A280: 280 | B280: Medline Disposable Nebulizer (Ref:HCS4485) | C280: Anesthesia / Airway / Respiratory | D280: Airway / respiratory | E280: HCS4485
A281: 281 | B281: Medline Ring Head Positioner (Ref: NON081141E) | C281: Patient Care / Hygiene / Comfort | D281: Patient care / comfort | E281: NON081141E
A282: 282 | B282: Medline Adult Head Positioner (Ref: NON081144) puple flat | C282: Patient Care / Hygiene / Comfort | D282: Patient care / comfort | E282: NON081144
...

Sheet Summary
A1: Category | B1: Count | C1: Notes
A2: Implants / Implant Accessories / Scaffolds | B2: =COUNTIF('By Category'!$A:$A,A2) -> 65 | C2: Breast implants, scaffold/mesh items, and implant insertion accessories.
A3: Sutures | B3: =COUNTIF('By Category'!$A:$A,A3) -> 69 | C3: Vicryl, PDS, Monocryl, Prolene, Ethibond, Ethilon, silk, gut, Quill, Stratafix, etc.
A4: Medications / Pharmaceuticals | B4: =COUNTIF('By Category'!$A:$A,A4) -> 89 | C4: Injectables, anesthesia drugs, emergency meds, antibiotics, peptides, eye drops, and other pharmaceuticals.
A5: IV Fluids / Irrigation Solutions | B5: =COUNTIF('By Category'!$A:$A,A5) -> 9 | C5: Lactated Ringer, saline injection/irrigation, BSS, and sterile irrigation solutions.
A6: Needles / Syringes / IV Access | B6: =COUNTIF('By Category'!$A:$A,A6) -> 36 | C6: Syringes, hypodermic/spinal needles, IV catheters, IV sets, extension sets, stopcocks, and blood collection sets.
A7: Anesthesia / Airway / Respiratory | B7: =COUNTIF('By Category'!$A:$A,A7) -> 33 | C7: Airway devices, endotracheal tubes, LMAs, cannulas, oxygen masks, circuits, laryngoscope, nebulizer, CO2 lines.
A8: Drains / Suction / Tubing / Canisters | B8: =COUNTIF('By Category'!$A:$A,A8) -> 25 | C8: Drains, Yankauers, suction/connective tubing, tubing connectors, suction canisters/liners, lipo tubing.
A9: Drapes / Covers / OR Linens | B9: =COUNTIF('By Category'!$A:$A,A9) -> 19 | C9: Drapes, covers, sheets, bed/table covers, underpads, and OR linens.
A10: Gauze / Sponges / Towels / Applicators | B10: =COUNTIF('By Category'!$A:$A,A10) -> 11 | C10: Lap sponges, gauze sponges, OR towels, cotton applicators, tonsil/peanut sponges.
A11: Dressings / Bandages / Tapes / Skin Closure | B11: =COUNTIF('By Category'!$A:$A,A11) -> 32 | C11: Pads, Tegaderm, Xeroform, Kerlix, tapes, bandages, skin strips, Dermabond, packing strips.
A12: PPE / Gloves / Masks / Staff Apparel | B12: =COUNTIF('By Category'!$A:$A,A12) -> 22 | C12: Exam/surgical gloves, caps, shoe covers, surgical gowns, masks, N95 respirators.
A13: Patient Garments / Compression / Supports | B13: =COUNTIF('By Category'!$A:$A,A13) -> 11 | C13: Stockings, binders, post-surgery bras, SCD/calf compression supports.
... A22: Uncategorized / Review | B22: =COUNTIF('By Category'!$A:$A,A22) -> 1 | C22: Items needing manual confirmation.
A24: Total inventory items | B24: =SUM(B2:B22) -> 508

Sheet Categories
A1: Category
A2: Implants / Implant Accessories / Scaffolds
A3: Sutures
A4: Medications / Pharmaceuticals
A5: IV Fluids / Irrigation Solutions
A6: Needles / Syringes / IV Access
A7: Anesthesia / Airway / Respiratory
A8: Drains / Suction / Tubing / Canisters
A9: Drapes / Covers / OR Linens
A10: Gauze / Sponges / Towels / Applicators
A11: Dressings / Bandages / Tapes / Skin Closure
A12: PPE / Gloves / Masks / Staff Apparel
... A22: Uncategorized / Review
